Workbook

Sheet Portafolio P&D
A2: N° | B2: Código de Planeamiento | C2: Nombre del Proyecto | D2: Alcance del Proyecto | E2: Gerencia Líder | F2: Líder del Proyecto | G2: Usuario Funcional | H2: Gestor de Planeamiento | I2: Presupuesto asignado | J2: Valor Ganado (EV) | K2: Costo Actual (AC) | L2: CPI | M2: Fecha Comité Ejec. Proy. | N2: N° Acta Comité (aprobación) | O2: Dimensión | P2: Objetivo | Q2: Año Inicio Planificado | R2: Año Fin Planificado | S2: N° Solicitudes de cambio | T2: Componente Tecnológico | U2: Transformación Digital | V2: Cartera | W2: Anexo 1 (Modelo de Negocio) | X2: Líder Técnico | Y2: Fecha Inicio | Z2: Fecha Fin | AA2: % Avance Planificado | AB2: % Avance ejecutado | AC2: Desv. % | AD2: Estado | AE2: SEGUIMIENTO (Planeamiento y Control de Gestión)
A3: 1 | B3: Iniciativa | C3: Proyecto 1 | E3: G1 | F3: Lider 1 | G3: Usuario 1 | H3: Gestor 1 | I3: =RANDBETWEEN(100,100000) -> 70305 | M3: =DATE(RANDBETWEEN(2020,2026),RANDBETWEEN(1,12),RANDBETWEEN(1,30)) -> 44724 | N3: 1 | O3: Dimension 1 | Q3: =YEAR(Tabla3[[#This Row],[Fecha Comité Ejec. Proy.]]) -> 2022 | R3: =Tabla3[[#This Row],[Año Inicio Planificado]] + 2 -> 2024 | S3: =RANDBETWEEN(1,4) -> 2 | V3: Cartera 1 | AA3: 0 | AB3: 0 | AC3: =Tabla3[[#This Row],[% Avance ejecutado]]-Tabla3[[#This Row],[% Avance Planificado]]/Tabla3[[#This Row],[% Avance Planificado]] -> #DIV/0! | AD3: 04. Cerrado
A4: 2 | B4: Iniciativa | C4: Proyecto 2 | E4: G1 | F4: Lider 2 | G4: Usuario 2 | H4: Gestor 2 | I4: =RANDBETWEEN(100,100000) -> 91002 | M4: =DATE(RANDBETWEEN(2020,2026),RANDBETWEEN(1,12),RANDBETWEEN(1,30)) -> 46074 | N4: 2 | O4: Dimension 1 | Q4: =YEAR(Tabla3[[#This Row],[Fecha Comité Ejec. Proy.]]) -> 2026 | R4: =Tabla3[[#This Row],[Año Inicio Planificado]] + 2 -> 2028 | S4: =RANDBETWEEN(1,4) -> 1 | V4: Cartera 1 | AA4: 0 | AB4: 0 | AC4: =Tabla3[[#This Row],[% Avance ejecutado]]-Tabla3[[#This Row],[% Avance Planificado]]/Tabla3[[#This Row],[% Avance Planificado]] -> #DIV/0! | AD4: 04. Cerrado
A5: 3 | B5: Iniciativa | C5: Proyecto 3 | E5: G1 | F5: Lider 3 | G5: Usuario 3 | H5: Gestor 3 | I5: =RANDBETWEEN(100,100000) -> 48611 | M5: =DATE(RANDBETWEEN(2020,2026),RANDBETWEEN(1,12),RANDBETWEEN(1,30)) -> 43840 | N5: 1 | O5: Dimension 1 | Q5: =YEAR(Tabla3[[#This Row],[Fecha Comité Ejec. Proy.]]) -> 2020 | R5: =Tabla3[[#This Row],[Año Inicio Planificado]] + 2 -> 2022 | S5: =RANDBETWEEN(1,4) -> 3 | V5: Cartera 1 | AA5: 0 | AB5: 0 | AC5: =Tabla3[[#This Row],[% Avance ejecutado]]-Tabla3[[#This Row],[% Avance Planificado]]/Tabla3[[#This Row],[% Avance Planificado]] -> #DIV/0! | AD5: 04. Cerrado
A6: 4 | B6: Iniciativa | C6: Proyecto 4 | E6: G1 | F6: Lider 4 | G6: Usuario 4 | H6: Gestor 4 | I6: =RANDBETWEEN(100,100000) -> 53926 | M6: =DATE(RANDBETWEEN(2020,2026),RANDBETWEEN(1,12),RANDBETWEEN(1,30)) -> 44409 | N6: 2 | O6: Dimension 1 | Q6: =YEAR(Tabla3[[#This Row],[Fecha Comité Ejec. Proy.]]) -> 2021 | R6: =Tabla3[[#This Row],[Año Inicio Planificado]] + 2 -> 2023 | S6: =RANDBETWEEN(1,4) -> 1 | V6: Cartera 1 | AA6: 0 | AB6: 0 | AC6: =Tabla3[[#This Row],[% Avance ejecutado]]-Tabla3[[#This Row],[% Avance Planificado]]/Tabla3[[#This Row],[% Avance Planificado]] -> #DIV/0! | AD6: 04. Cerrado
A7: 5 | C7: Proyecto 5 | E7: G1 | F7: Lider 5 | G7: Usuario 5 | H7: Gestor 5 | I7: =RANDBETWEEN(100,100000) -> 42718 | M7: =DATE(RANDBETWEEN(2020,2026),RANDBETWEEN(1,12),RANDBETWEEN(1,30)) -> 45887 | N7: 2 | O7: Dimension 1 | Q7: =YEAR(Tabla3[[#This Row],[Fecha Comité Ejec. Proy.]]) -> 2025 | R7: =Tabla3[[#This Row],[Año Inicio Planificado]] + 2 -> 2027 | S7: =RANDBETWEEN(1,4) -> 4 | V7: Cartera 1 | AA7: 0.88 | AB7: 0.85 | AC7: =Tabla3[[#This Row],[% Avance ejecutado]]-Tabla3[[#This Row],[% Avance Planificado]]/Tabla3[[#This Row],[% Avance Planificado]] -> -0.15 | AD7: 02. En Curso
A8: 6 | C8: Proyecto 6 | E8: G1 | F8: Lider 6 | G8: Usuario 6 | H8: Gestor 6 | I8: =RANDBETWEEN(100,100000) -> 47299 | M8: =DATE(RANDBETWEEN(2020,2026),RANDBETWEEN(1,12),RANDBETWEEN(1,30)) -> 45106 | N8: 2.2 | O8: Dimension 1 | Q8: =YEAR(Tabla3[[#This Row],[Fecha Comité Ejec. Proy.]]) -> 2023 | R8: =Tabla3[[#This Row],[Año Inicio Planificado]] + 2 -> 2025 | S8: =RANDBETWEEN(1,4) -> 3 | V8: Cartera 1 | AA8: 0.87 | AB8: 0.84 | AC8: =Tabla3[[#This Row],[% Avance ejecutado]]-Tabla3[[#This Row],[% Avance Planificado]]/Tabla3[[#This Row],[% Avance Planificado]] -> -0.16 | AD8: 02. En Curso
A9: 7 | C9: Proyecto 7 | E9: G1 | F9: Lider 7 | G9: Usuario 7 | H9: Gestor 7 | I9: =RANDBETWEEN(100,100000) -> 14855 | M9: =DATE(RANDBETWEEN(2020,2026),RANDBETWEEN(1,12),RANDBETWEEN(1,30)) -> 45372 | N9: 2.4 | O9: Dimension 1 | Q9: =YEAR(Tabla3[[#This Row],[Fecha Comité Ejec. Proy.]]) -> 2024 | R9: =Tabla3[[#This Row],[Año Inicio Planificado]] + 2 -> 2026 | S9: =RANDBETWEEN(1,4) -> 2 | V9: Cartera 1 | AA9: 0.76 | AB9: 0.71 | AC9: =Tabla3[[#This Row],[% Avance ejecutado]]-Tabla3[[#This Row],[% Avance Planificado]]/Tabla3[[#This Row],[% Avance Planificado]] -> -0.29 | AD9: 02. En Curso
A10: 8 | C10: Proyecto 8 | E10: G1 | F10: Lider 8 | G10: Usuario 8 | H10: Gestor 8 | I10: =RANDBETWEEN(100,100000) -> 86061 | M10: =DATE(RANDBETWEEN(2020,2026),RANDBETWEEN(1,12),RANDBETWEEN(1,30)) -> 45932 | N10: 2.6 | O10: Dimension 1 | Q10: =YEAR(Tabla3[[#This Row],[Fecha Comité Ejec. Proy.]]) -> 2025 | R10: =Tabla3[[#This Row],[Año Inicio Planificado]] + 2 -> 2027 | S10: =RANDBETWEEN(1,4) -> 4 | V10: Cartera 1 | AA10: 0.97 | AB10: 0.97 | AC10: =Tabla3[[#This Row],[% Avance ejecutado]]-Tabla3[[#This Row],[% Avance Planificado]]/Tabla3[[#This Row],[% Avance Planificado]] -> -0.03 | AD10: 02. En Curso
A11: 9 | C11: Proyecto 9 | E11: G1 | F11: Lider 9 | G11: Usuario 9 | H11: Gestor 9 | I11: =RANDBETWEEN(100,100000) -> 24869 | M11: =DATE(RANDBETWEEN(2020,2026),RANDBETWEEN(1,12),RANDBETWEEN(1,30)) -> 43848 | N11: 2.8 | O11: Dimension 1 | Q11: =YEAR(Tabla3[[#This Row],[Fecha Comité Ejec. Proy.]]) -> 2020 | R11: =Tabla3[[#This Row],[Año Inicio Planificado]] + 2 -> 2022 | S11: =RANDBETWEEN(1,4) -> 2 | V11: Cartera 1 | AC11: =Tabla3[[#This Row],[% Avance ejecutado]]-Tabla3[[#This Row],[% Avance Planificado]]/Tabla3[[#This Row],[% Avance Planificado]] -> #DIV/0! | AD11: 02. En Curso
A12: 10 | C12: Proyecto 10 | E12: G1 | F12: Lider 10 | G12: Usuario 10 | H12: Gestor 10 | I12: =RANDBETWEEN(100,100000) -> 3975 | M12: =DATE(RANDBETWEEN(2020,2026),RANDBETWEEN(1,12),RANDBETWEEN(1,30)) -> 44450 | N12: 3 | O12: Dimension 1 | Q12: =YEAR(Tabla3[[#This Row],[Fecha Comité Ejec. Proy.]]) -> 2021 | R12: =Tabla3[[#This Row],[Año Inicio Planificado]] + 2 -> 2023 | S12: =RANDBETWEEN(1,4) -> 2 | V12: Cartera 1 | AA12: 1 | AB12: 1 | AC12: =Tabla3[[#This Row],[% Avance ejecutado]]-Tabla3[[#This Row],[% Avance Planificado]]/Tabla3[[#This Row],[% Avance Planificado]] -> 0 | AD12: 03. Implementado
A13: 11 | C13: Proyecto 11 | E13: G1 | F13: Lider 11 | G13: Usuario 11 | H13: Gestor 11 | I13: =RANDBETWEEN(100,100000) -> 52281 | M13: =DATE(RANDBETWEEN(2020,2026),RANDBETWEEN(1,12),RANDBETWEEN(1,30)) -> 44282 | N13: 3.2 | O13: Dimension 1 | Q13: =YEAR(Tabla3[[#This Row],[Fecha Comité Ejec. Proy.]]) -> 2021 | R13: =Tabla3[[#This Row],[Año Inicio Planificado]] + 2 -> 2023 | S13: =RANDBETWEEN(1,4) -> 3 | V13: Cartera 1 | AA13: 1 | AB13: 1 | AC13: =Tabla3[[#This Row],[% Avance ejecutado]]-Tabla3[[#This Row],[% Avance Planificado]]/Tabla3[[#This Row],[% Avance Planificado]] -> 0 | AD13: 03. Implementado
A14: 12 | C14: Proyecto 12 | E14: G1 | F14: Lider 12 | G14: Usuario 12 | H14: Gestor 12 | I14: =RANDBETWEEN(100,100000) -> 27557 | M14: =DATE(RANDBETWEEN(2020,2026),RANDBETWEEN(1,12),RANDBETWEEN(1,30)) -> 45056 | N14: 3.4 | O14: Dimension 1 | Q14: =YEAR(Tabla3[[#This Row],[Fecha Comité Ejec. Proy.]]) -> 2023 | R14: =Tabla3[[#This Row],[Año Inicio Planificado]] + 2 -> 2025 | S14: =RANDBETWEEN(1,4) -> 4 | V14: Cartera 1 | AA14: 1 | AB14: 1 | AC14: =Tabla3[[#This Row],[% Avance ejecutado]]-Tabla3[[#This Row],[% Avance Planificado]]/Tabla3[[#This Row],[% Avance Planificado]] -> 0 | AD14: 03. Implementado
A15: 13 | C15: Proyecto 13 | E15: G1 | F15: Lider 13 | G15: Usuario 13 | H15: Gestor 13 | I15: =RANDBETWEEN(100,100000) -> 5578 | M15: =DATE(RANDBETWEEN(2020,2026),RANDBETWEEN(1,12),RANDBETWEEN(1,30)) -> 46380 | N15: 3.6 | O15: Dimension 1 | Q15: =YEAR(Tabla3[[#This Row],[Fecha Comité Ejec. Proy.]]) -> 2026 | R15: =Tabla3[[#This Row],[Año Inicio Planificado]] + 2 -> 2028 | S15: =RANDBETWEEN(1,4) -> 1 | V15: Cartera 1 | AA15: 0.44 | AB15: 0.4 | AC15: =Tabla3[[#This Row],[% Avance ejecutado]]-Tabla3[[#This Row],[% Avance Planificado]]/Tabla3[[#This Row],[% Avance Planificado]] -> -0.6 | AD15: 04. Cerrado
A16: 14 | C16: Proyecto 14 | E16: G1 | F16: Lider 14 | G16: Usuario 14 | H16: Gestor 14 | I16: =RANDBETWEEN(100,100000) -> 4467 | M16: =DATE(RANDBETWEEN(2020,2026),RANDBETWEEN(1,12),RANDBETWEEN(1,30)) -> 43866 | N16: 3.8 | O16: Dimension 1 | Q16: =YEAR(Tabla3[[#This Row],[Fecha Comité Ejec. Proy.]]) -> 2020 | R16: =Tabla3[[#This Row],[Año Inicio Planificado]] + 2 -> 2022 | S16: =RANDBETWEEN(1,4) -> 2 | V16: Cartera 1 | AA16: 1 | AB16: 1 | AC16: =Tabla3[[#This Row],[% Avance ejecutado]]-Tabla3[[#This Row],[% Avance Planificado]]/Tabla3[[#This Row],[% Avance Planificado]] -> 0 | AD16: 03. Implementado
A17: 15 | C17: Proyecto 15 | E17: G1 | F17: Lider 15 | G17: Usuario 15 | H17: Gestor 15 | I17: =RANDBETWEEN(100,100000) -> 40631 | M17: =DATE(RANDBETWEEN(2020,2026),RANDBETWEEN(1,12),RANDBETWEEN(1,30)) -> 44054 | N17: 4 | O17: Dimension 1 | Q17: =YEAR(Tabla3[[#This Row],[Fecha Comité Ejec. Proy.]]) -> 2020 | R17: =Tabla3[[#This Row],[Año Inicio Planificado]] + 2 -> 2022 | S17: =RANDBETWEEN(1,4) -> 3 | V17: Cartera 2 | AA17: 1 | AB17: 1 | AC17: =Tabla3[[#This Row],[% Avance ejecutado]]-Tabla3[[#This Row],[% Avance Planificado]]/Tabla3[[#This Row],[% Avance Planificado]] -> 0 | AD17: 03. Implementado
A18: 16 | C18: Proyecto 16 | E18: G1 | F18: Lider 16 | G18: Usuario 16 | H18: Gestor 16 | I18: =RANDBETWEEN(100,100000) -> 47889 | M18: =DATE(RANDBETWEEN(2020,2026),RANDBETWEEN(1,12),RANDBETWEEN(1,30)) -> 43933 | N18: 4.2 | O18: Dimension 1 | Q18: =YEAR(Tabla3[[#This Row],[Fecha Comité Ejec. Proy.]]) -> 2020 | R18: =Tabla3[[#This Row],[Año Inicio Planificado]] + 2 -> 2022 | S18: =RANDBETWEEN(1,4) -> 2 | V18: Cartera 2 | AA18: 0.56 | AB18: 0.47 | AC18: =Tabla3[[#This Row],[% Avance ejecutado]]-Tabla3[[#This Row],[% Avance Planificado]]/Tabla3[[#This Row],[% Avance Planificado]] -> -0.53 | AD18: 02. En Curso
A19: 17 | C19: Proyecto 17 | E19: G1 | F19: Lider 17 | G19: Usuario 17 | H19: Gestor 17 | I19: =RANDBETWEEN(100,100000) -> 43642 | M19: =DATE(RANDBETWEEN(2020,2026),RANDBETWEEN(1,12),RANDBETWEEN(1,30)) -> 44334 | N19: 4.4 | O19: Dimension 1 | Q19: =YEAR(Tabla3[[#This Row],[Fecha Comité Ejec. Proy.]]) -> 2021 | R19: =Tabla3[[#This Row],[Año Inicio Planificado]] + 2 -> 2023 | S19: =RANDBETWEEN(1,4) -> 3 | V19: Cartera 2 | AA19: 0.71 | AB19: 0.6 | AC19: =Tabla3[[#This Row],[% Avance ejecutado]]-Tabla3[[#This Row],[% Avance Planificado]]/Tabla3[[#This Row],[% Avance Planificado]] -> -0.4 | AD19: 04. Cerrado
A20: 18 | C20: Proyecto 18 | E20: G1 | F20: Lider 18 | G20: Usuario 18 | H20: Gestor 18 | I20: =RANDBETWEEN(100,100000) -> 75723 | M20: =DATE(RANDBETWEEN(2020,2026),RANDBETWEEN(1,12),RANDBETWEEN(1,30)) -> 44596 | N20: 4.6 | O20: Dimension 1 | Q20: =YEAR(Tabla3[[#This Row],[Fecha Comité Ejec. Proy.]]) -> 2022 | R20: =Tabla3[[#This Row],[Año Inicio Planificado]] + 2 -> 2024 | S20: =RANDBETWEEN(1,4) -> 4 | V20: Cartera 2 | AA20: 1 | AB20: 1 | AC20: =Tabla3[[#This Row],[% Avance ejecutado]]-Tabla3[[#This Row],[% Avance Planificado]]/Tabla3[[#This Row],[% Avance Planificado]] -> 0 | AD20: 03. Implementado
A21: 19 | C21: Proyecto 19 | E21: G1 | F21: Lider 19 | G21: Usuario 19 | H21: Gestor 19 | I21: =RANDBETWEEN(100,100000) -> 92119 | M21: =DATE(RANDBETWEEN(2020,2026),RANDBETWEEN(1,12),RANDBETWEEN(1,30)) -> 46279 | N21: 4.8 | O21: Dimension 1 | Q21: =YEAR(Tabla3[[#This Row],[Fecha Comité Ejec. Proy.]]) -> 2026 | R21: =Tabla3[[#This Row],[Año Inicio Planificado]] + 2 -> 2028 | S21: =RANDBETWEEN(1,4) -> 3 | V21: Cartera 2 | AA21: 0 | AB21: 0 | AC21: =Tabla3[[#This Row],[% Avance ejecutado]]-Tabla3[[#This Row],[% Avance Planificado]]/Tabla3[[#This Row],[% Avance Planificado]] -> #DIV/0! | AD21: 03. Implementado
A22: 20 | C22: Proyecto 20 | E22: G1 | F22: Lider 20 | G22: Usuario 20 | H22: Gestor 20 | I22: =RANDBETWEEN(100,100000) -> 4481 | M22: =DATE(RANDBETWEEN(2020,2026),RANDBETWEEN(1,12),RANDBETWEEN(1,30)) -> 45483 | N22: 5 | O22: Dimension 1 | Q22: =YEAR(Tabla3[[#This Row],[Fecha Comité Ejec. Proy.]]) -> 2024 | R22: =Tabla3[[#This Row],[Año Inicio Planificado]] + 2 -> 2026 | S22: =RANDBETWEEN(1,4) -> 3 | V22: Cartera 2 | AA22: 1 | AB22: 1 | AC22: =Tabla3[[#This Row],[% Avance ejecutado]]-Tabla3[[#This Row],[% Avance Planificado]]/Tabla3[[#This Row],[% Avance Planificado]] -> 0 | AD22: 03. Implementado
A23: 21 | C23: Proyecto 21 | E23: G1 | F23: Lider 21 | G23: Usuario 21 | H23: Gestor 21 | I23: =RANDBETWEEN(100,100000) -> 19054 | M23: =DATE(RANDBETWEEN(2020,2026),RANDBETWEEN(1,12),RANDBETWEEN(1,30)) -> 44080 | N23: 5.2 | O23: Dimension 1 | Q23: =YEAR(Tabla3[[#This Row],[Fecha Comité Ejec. Proy.]]) -> 2020 | R23: =Tabla3[[#This Row],[Año Inicio Planificado]] + 2 -> 2022 | S23: =RANDBETWEEN(1,4) -> 1 | V23: Cartera 2 | AA23: 1 | AB23: 1 | AC23: =Tabla3[[#This Row],[% Avance ejecutado]]-Tabla3[[#This Row],[% Avance Planificado]]/Tabla3[[#This Row],[% Avance Planificado]] -> 0 | AD23: 03. Implementado
... A42: 40 | C42: Proyecto 40 | E42: G2 | F42: Lider 40 | G42: Usuario 40 | H42: Gestor 40 | I42: =RANDBETWEEN(100,100000) -> 37568 | M42: =DATE(RANDBETWEEN(2020,2026),RANDBETWEEN(1,12),RANDBETWEEN(1,30)) -> 44800 | N42: 9 | O42: Dimension 2 | Q42: =YEAR(Tabla3[[#This Row],[Fecha Comité Ejec. Proy.]]) -> 2022 | R42: =Tabla3[[#This Row],[Año Inicio Planificado]] + 2 -> 2024 | S42: =RANDBETWEEN(1,4) -> 4 | V42: Cartera 2 | AA42: 0.6 | AB42: 0.26 | AC42: =Tabla3[[#This Row],[% Avance ejecutado]]-Tabla3[[#This Row],[% Avance Planificado]]/Tabla3[[#This Row],[% Avance Planificado]] -> -0.74 | AD42: 04. Cerrado
A43: 41 | B43: Iniciativa | C43: Proyecto 41 | E43: G2 | F43: Lider 41 | G43: Usuario 41 | H43: Gestor 41 | I43: =RANDBETWEEN(100,100000) -> 2574 | J43: =Tabla3[[#This Row],[Presupuesto asignado]]/2 -> 1287 | K43: =Tabla3[[#This Row],[Valor Ganado (EV)]] -> 1287 | L43: =Tabla3[[#This Row],[Valor Ganado (EV)]]/Tabla3[[#This Row],[Costo Actual (AC)]] -> 1 | M43: =DATE(RANDBETWEEN(2020,2026),RANDBETWEEN(1,12),RANDBETWEEN(1,30)) -> 46052 | N43: 9.2 | O43: Dimension 2 | Q43: =YEAR(Tabla3[[#This Row],[Fecha Comité Ejec. Proy.]]) -> 2026 | R43: =Tabla3[[#This Row],[Año Inicio Planificado]] + 2 -> 2028 | S43: =RANDBETWEEN(1,4) -> 2 | V43: Cartera 2 | AA43: 0 | AB43: 0 | AC43: =Tabla3[[#This Row],[% Avance ejecutado]]-Tabla3[[#This Row],[% Avance Planificado]]/Tabla3[[#This Row],[% Avance Planificado]] -> #DIV/0! | AD43: 01. No Iniciado

Sheet Demanda Estrategica CT
A1: TOTAL: | C1: =COUNT(DemandaEstrateg_[ID]) -> 111 | F1: =TODAY() -> 46150
A2: SEGUIMIENTO DE LA DEMANDA ESTRATÉGICA
AK3: OK | AL3: OK | AM3: OK | AN3: PENDIENTE | AO3: PENDIENTE
A4: ID | B4: ID Trámite | C4: ID Dependencia | D4: ID Proyecto / Mantenimiento asociado | E4: Tipo de Requerimiento | F4: Nombre del Proyecto | G4: Alcance del Proyecto | H4: Gerencia Líder | I4: Líder del Proyecto | J4: Usuario Funcional | K4: Gestor de Planeamiento | L4: Fecha de Solicitud a TI | M4: Memorando STD | N4: Canal de Atención | O4: Producto | P4: Servicio | Q4: Categoría | R4: Entidad reguladora / Organo de Control | S4: N° Norma / N° Informe | T4: N° recomendación | U4: Año Inicio Planificado | V4: Año Fin Planificado | W4: Fecha de Aprobación en Comité | X4: Presupuesto asignado | Y4: Cartera | Z4: Gestor TI | AA4: Aplicativo | AB4: Área Responsable TI | AC4: Entidad / Proveedor Asignado | AD4: Líder Técnico | AE4: Analista asignado | AF4: Motivo según estado | AG4: Fecha registro trámite | AH4: Fecha Inicio- Plan | AI4: Fecha Fin- Plan | AJ4: Fecha Fin Ral (CQ) | AK4: % Avance Planificado | AL4: % Avance ejecutado | AM4: Desv. % | AN4: Días faltantes | AO4: ALERTA | AP4: Fecha Fin TI Propuesta | AQ4: Fecha Fin TI (Trimestre) | AR4: Últ. Estado CQ 30.04 | AS4: Estado TI | AT4: Estado Proyecto TI | AU4: Seguimiento OPP | AV4: Código de Planeamiento
A5: 1 | E5: Proyecto | F5: Proyecto 1 | H5: G1 | AH5: ='Portafolio P&D'!Y11 -> 0 | AI5: 46142 | AK5: ='Portafolio P&D'!AA11 -> 0 | AL5: ='Portafolio P&D'!AB11 -> 0 | AM5: =IF(DemandaEstrateg_[[#This Row],[Tipo de Requerimiento]]="Proyecto",(DemandaEstrateg_[[#This Row],[% Avance ejecutado]]-DemandaEstrateg_[[#This Row],[% Avance Planificado]])/DemandaEstrateg_[[#This Row],[% Avance Planificado]],"No aplica") -> #DIV/0! | AN5: =IF(DemandaEstrateg_[[#This Row],[Tipo de Requerimiento]]="Proyecto",(DemandaEstrateg_[[#This Row],[% Avance ejecutado]]-DemandaEstrateg_[[#This Row],[% Avance Planificado]])/DemandaEstrateg_[[#This Row],[% Avance Planificado]],"No aplica") -> #DIV/0! | AP5: 46113 | AQ5: 2026-I | AR5: No Aplica | AS5: 03. En Desarrollo | AT5: =VLOOKUP(DemandaEstrateg_[[#This Row],[Estado TI]],#REF!,3,FALSE) -> #REF! | AU5: 14/01/2026: El estado es el sgte: Entregable 7 (fase 1): Certificado en 12/2024. Entregable 7 (fase 2): A espera que el proveedor confirme inicio de pruebas en Calidad. Oplaft remitirá solicitud de enmascaramiento de data de prueba traida de Producción. Entregable 9: A espera que el Proveedor brinde disponibilidad para realizar las pruebas técnicas de integración en el mes de enero, para luego continuar con las pruebas de usuario. Entregable 10: Paso a producción el 28/11, se hicieron ajustes de configuración hasta el 10/12 informando su puesta en producción. Entregable 12: Certificado en 12/2024. Existen vulnerabilidades pendientes, respecto al cual el proveedor a remitido su compromiso (correo) para ser subsanado en May26. En coordinación con el proveedor, se están llevando a cabo reuniones para actualizar el cronograma del Proyecto. 15/12/2025: El estado es el sgte: Entregable 7 (fase 1): Certificado en 12/2024. Entregable 7 (fase 2): A espera que el proveedor confirme inicio de pruebas en Calidad. Entregable 9: Se están realizando nuevas pruebas técnicas de integración, para continuar con las pruebas de usuario. Entregable 10: Paso a producción el 28/11, se hicieron ajustes de configuración hasta el 10/12 informando su puesta en producción. Entregable 12: Certificado en 12/2024. Existen vulnerabilidades pendientes, respecto al cual el proveedor a remitido su compromiso (correo) para ser subsanado en May26. Existe un plan a alto nivel propuesto por el Proveedor, sobre el cual se están ejecutando las actividades. 05/09/2025: El estado es el sgte: Entregable 7 (fase 1): Certificado el 12/2024. Entregable 7 (fase 2): En adecuaciones de las transacciones faltantes, compromiso 15-Oct-25. Entregable 9: Pruebas técnicas culminaron, se está actualizando el mapeo técnico/funcional, el Proveedor está actualizando la versión de Sentinel en desarrollo (15 días). Entregable 10: Certificado el 06/2025 Entregable 12: Certificado 12/2024. BN ejecutó en Jul-25 un nuevo de análisis de vulnerabilidad en certificación, donde se evidencia que las vulnerabilidades permanecen. Pendiente reunión para revisar los resultados de las pruebas de rendimiento que efectuó el proveedor. En reunión con los usuarios de Riesgos, Oplaft y Fraudes se estableció hitos de pase a producción: Entregable 10 y 12 (Dic2025), Entregable 7 y Entregable 9 (Mar2026). Está pendiente que el usuario gestione la ampliación de plazo e informar a Planeamiento. 25/07/2025: Entregable 7 (fase 1): Certificado el 12/2024; Entregable 7 (fase 2): Se culmino con la generación y entrega de data de 6 meses. A la espera que el proveedor complete el despliegue en calidad y confirme el inicio de las pruebas; Entregable 9: Se están realizando nuevas pruebas técnicas en los canales, de acuerdo a lo solicitado por el proveedor.; Entregable 10: Certificado el 06/2025; Entregable 12: Certificado 12/2024. BN ejecutó un nuevo de analisis de vulnerabilidad en el ambiente de certificación la semana del 14 al 18/07 donde se evidencia que las vulnerabilidades permanecen, se remitirá informe al Proveedor reiterando se subsanen las vulnerabilidades, como tambien se subsane las observaciones de las pruebas de rendimiento; antes de un pase a Producción. 11/06/2025:Según la información enviada de 17/07/2025: Entregable 7 (fase 1): Certificado el 12/2024; Entregable 7 (fase 2): Se culmino con la generación y entrega de data de 6 meses. A la espera que el proveedor complete el despliegue en calidad y confirme el inicio de las pruebas; Entregable 9: Se están realizando nuevas pruebas técnicas en los canales del alcance, de acuerdo a lo solicitado por el proveedor.; Entregable 10: Certificado 06/2025; Entregable 12: Certificado 12/2024; Pendiente que el proveedor resuelva las observaciones de vulnerabilidades y pruebas de rendimiento, antes de un pase a Producción. 11/06/2025:Según la información enviada de Planeamiento en el mes de Mayo se precisa lo siguiente: Entregable 7 Fase 2 Ambiente de Desarrollo continúan las pruebas de perfiles ,funcionales y la validación de Calidad de datos de los archivos de 5 días, en paralelo se están generando desde 2/5 los archivos de 6 meses con los programas extractores v2 . Entregable 9 se culmino la integración de datos desde los canales en el ambiente Desarrollo. Entregable 10 se culmino las pruebas en el ambiente de Certificación esta en proceso la firma de los IRPF y RC . 03/06/2025: Según la información enviada de Planeamiento mediante correo respecto al proyecto en el mes de abril se tiene que: Se encuentra en actualización el Cronograma entre el BN y SS el cual generara la versión 3. Se desplego la versión 7.12.1 de Sentinel Core y Predictions en el ambiente de desarrollo. 07/05/2025: Según la información remitida por Planeamiento mediante correo: Se esta desplegando la nueva versión de Sentinel Core y Predictions que resuelve issues identificadas durante las pruebas hasta dic 2024. Entregable 7 La revisión de Calidad de datos no se esta cumpliendo en fecha debido a la que la información aun sigue siendo corregida por parte de TI-BN , existe una alta dependencia de un solo especialista para el análisis y construcción de los programas extractores . Entregable 9 Hay retraso en el inicio de las pruebas funcionales en el ambiente de desarrollo debido a las actividades previas por parte de TI-BN y Smartsoft. Entregable 10 Aún están pendientes de firma las RC , ya que dependen de los IRPF, tanto de Producto como Funcional, los cuales no han sido remitidos con las firmas correspondientes por parte de Smartsoft. Una vez que Smartsoft entregue los IRPF debidamente visados, los usuarios y el equipo de TI - BN procederán con el visado final para su cierre. 31/12/2024: A nivel entregables se encuentran en ejecución 4 entregables. OPLAFT El entregable 7 se encuentra a un 86 %. Se culmino la certificación de la Fase 1 (Productos y Perfiles). Fraudes El entregable 9 se encuentra a un 70 %. Se definió el tema de las pruebas RT y NRT . El entregable 10 se encuentra a un 65 %. El entregable 12 se encuentra a un 92 % Se culmino la certificación. 23/05/2024 Mediante Comité Estratégico de proyectos de fecha 06.05.24 se informa la aprobación de control de cambios del proyecto 08/04/24 Se ha cambiado la fecha de inicio de proyecto de 2023 a 2021 20/03/24 TI compartirá con Planeamiento el nuevo plan actualizado para que se gestione el control de cambios con el Líder del Proyecto. 03/06/2025: Según la información enviada de Planeamiento mediante correo respecto al proyecto en el mes de abril se tiene que: Se encuentra en actualización el Cronograma entre el BN y SS el cual generara la versión 3. Se desplego la versión 7.12.1 de Sentinel Core y Predictions en el ambiente de desarrollo. 08/05/25: A espera de actas visadas por el área usuaria del Entregable 10 para su certificación. Se ejecuto las pruebas de rendimiento, pero con observaciones remitidos al Proveedor y BNDesa. Respecto al Entregable 7, se encuentra en proceso de despliegue de la nueva version Sentinel Core y Reporter en el ambiente de Calidad para iniciar las pruebas del Entregable 7 (fase2). 04/04/25: Del Entregable 10 se concluyeron con las pruebas funcionales. A la espera de actas visadas por el área usuaria y el proveedor para su certificación. Se está culminando las pruebas de rendimiento y está en proceso de elaboración del informe. Respecto al Entregable 9 se inició con las pruebas del producto y perfiles el 25/03 en Desarrollo. Se espera iniciar las pruebas funcionales la 2da semana de abril luego de que el proveedor culmine con la configuración de reglas de los canales. Respecto al Entregable 7 (fase 2), queda pendiente culminar solo las pruebas de calidad de datos en coordinación diaria con construcción, usuario y proveedor. 21/03/25: Mediante correo del 21/03/25 de Planeamiento se indica: Entregable 7: 86% Entregable 9: 72% Entregable 10: 81% Entregable 12: 93% 03/03/25: Se concluyeron con las pruebas funcionales del entregable 10 (en firma de actas) y se iniciarán con las pruebas de rendimiento. Respecto al entregable 9, se estima iniciar el 05/03 las pruebas funcionales en Desarrollo (previa confirmación del proveedor). Respecto al entregable 7 (fase 2), continuan las pruebas de calidad de datos en coordinación diaria con construcción, usuario y proveedor, ademas se culminaron con lsa pruebas del producto (en firma de actas por parte del proveedor y usuarios), perfiles (en elaboración de actas, pruebas funcionales (avanzando en coordinaciones entre el usuario y proveedor). 31/01/25: Se inició las pruebas del entregable 10 en Calidad. Se continuan con las pruebas del entregable 7 (fase 2) con demora por parte del proveedor en resolver las observaciones; tambien se están realizando pruebas de integración del entregable 9. 31/12/24: A nivel entregables se encuentran en ejecución 4 entregables. OPLAFT El entregable 7 se encuentra a un 86 %. Se culmino la certificación de la Fase 1 (Productos y Perfiles). Fraudes El entregable 9 se encuentra a un 70 %. Se definió el tema de las pruebas RT y NRT . El entregable 10 se encuentra a un 65 %. El entregable 12 se encuentra a un 92 % Se culmino la certificación. 24/10/24 El proyecto se encuentra en proceso de implementación, en base a una estrategia definida para sacar el proyecto en el presente año 2024 con el proyecto 7 y 12. 26/09/2023: En coordinación con Construcción se creó el ID de Proyecto, para almanenar toda la informacion referente al proyecto de forma integral en todas sus etapas de integración. | AV5: ='Portafolio P&D'!B11 -> 0
A6: 2 | E6: Proyecto-Hijo | F6: Proyecto 2 | H6: G1 | AH6: 44963 | AI6: 45838 | AK6: No aplica | AL6: No aplica | AM6: =IF(DemandaEstrateg_[[#This Row],[Tipo de Requerimiento]]="Proyecto",(DemandaEstrateg_[[#This Row],[% Avance ejecutado]]-DemandaEstrateg_[[#This Row],[% Avance Planificado]])/DemandaEstrateg_[[#This Row],[% Avance Planificado]],"No aplica") -> No aplica | AN6: =IF(DemandaEstrateg_[[#This Row],[Tipo de Requerimiento]]="Proyecto",(DemandaEstrateg_[[#This Row],[% Avance ejecutado]]-DemandaEstrateg_[[#This Row],[% Avance Planificado]])/DemandaEstrateg_[[#This Row],[% Avance Planificado]],"No aplica") -> No aplica | AP6: 46082 | AQ6: 2026-I | AR6: Certificado | AS6: =VLOOKUP(DemandaEstrateg_[[#This Row],[Últ. Estado CQ 30.04]],#REF!,3,FALSE) -> #REF! | AT6: =VLOOKUP(DemandaEstrateg_[[#This Row],[Estado TI]],#REF!,3,FALSE) -> #REF! | AU6: 5/12/2024: Según CQ, se actualizó el estado de 03. En Desarrollo a 05. En Calidad 13/12/2023: COMITÉ DEMANDA REGULARIZACIÓN: Se regulariza su registro según lo aprobado en comité 29/09/2023: Se observa retraso en las actividades por obervaciones encontradas en lo extractores, se estima se concluya el 06/10. Los roles y perfiles ya fueron unificados por los usuarios, se espera pruebas para validar que los roles funcionales y de seguridad funcionen correctamente. Pendiente que el proveedor concluya con sus actividades de desarrollo del componente de seguridad como de los procesos de consolidación y configuracion de reglas de PLAYFT. 26/09/2023: De acuerdo al compromiso de Construcción con GG, las obs de los extractores culminarán el 29/09. 19/09/2023: En coordinación con JRuiz y MArquiñigo los archivos extractores será remitidos hoy al proveedor con la validación a nivel de estructura. Respecto a las obs a nivel de data se seguirá revisando y corrigiendo hasta antes del pase a Calidad. 31/07/2023: Se actualizaron las fechas según lo conversado con Jorge Ruiz 19/06/2023: Se actualizó la fecha de fin de producción de acuerdo al cronograma de Sentinel. 17/05/2023: Se actualiza su prioridad (adquirida) 27/01/2023: Se avanzó el analisis y mapeo técnico de OPLAFT, se remitió al usuario para que valide y se envié luego a Fabrica para su desarrollo. Respecto a Fraudes, está pendiente que el usuario confirme la entrega del mapeo segun lo que indica las bases para continuar con el analisis y mapeo técnico. ---------------------------------------------------------------------------------- 07/06: Líder técnico no está claramente definido. Indicado por MCarbajo 30/05: Gestor anterior. Omar Sarmiento 10/05: Luis García, solicita culminación de mapeo de datos de movimientos y transacciones de Mario Carbajo (3 semanas sin rpta del mail). Se indicó que como hay sobrecarga laboral de Mario, de acuerdo a la reunión de hoy al medio día se validará dicha carga laboral con Carmen Iriarte. Mario depende de disponibilidad de tiempo de Carmen para tener dicha reunión. 24/03: Mario Carbajo indico que el 28/03 se incorporaria 1 recurso de OLSSA para mapeo y construcción de extractores. 15/03: Arquitectura compartio el TDR para el Middleware para revisión de las sub-gerencias del TI. 11/02: Ante la licencia solicitada por el líder de integración (Mario Carbajo) hasta el 08/03, queda como líder de integración Jorge Pazos. 10/02: Se identificaron y priorizaron las principales transacciones por Canal para la Entidad Movimiento y Transacciones. 03/02: Se entregó el Mapeo de datos para la Entidad Clientes. 02/02: Se continua con el mapo de entidades de cliente, y esto está demorando por encontrarse en diferentes BD (incluye Excel). 05/01: Se modifica las fechas al año y medio faltante que indicó el usuario se espera para concluir el proyecto. 04/01: La subdivisión de una sola actividad de mapeo de datos la cual se particiona en 5 mapeos. Productos (100%), Catálogos (100%), Data histórica (100%), Clientes (50%- Le falta una parte) y Movimiento y transacciones (0%- Banca celular, ventanilla, ATM y Told). 28/12: Solo una persona asignado (LI). Se ha avanzado el mapeo y extractores de catálogos y productos. El de clientes es más complejo. Transacciones y movimientos ya hubo reunión la semana pasada.La prox semana habrá reunión con Sentinel. 22/12: De 5 partes del proyecto se ha mepado Productos, catálogos y una parte de clientes. Lo que es movimientos y transacciones aún no está contemplado como parte del mapeo. | AV6: No Aplica
A7: 3 | E7: Proyecto-Hijo | F7: Proyecto 3 | H7: G1 | AH7: 45161 | AI7: 45723 | AK7: No aplica | AL7: No aplica | AM7: =IF(DemandaEstrateg_[[#This Row],[Tipo de Requerimiento]]="Proyecto",(DemandaEstrateg_[[#This Row],[% Avance ejecutado]]-DemandaEstrateg_[[#This Row],[% Avance Planificado]])/DemandaEstrateg_[[#This Row],[% Avance Planificado]],"No aplica") -> No aplica | AN7: =IF(DemandaEstrateg_[[#This Row],[Tipo de Requerimiento]]="Proyecto",(DemandaEstrateg_[[#This Row],[% Avance ejecutado]]-DemandaEstrateg_[[#This Row],[% Avance Planificado]])/DemandaEstrateg_[[#This Row],[% Avance Planificado]],"No aplica") -> No aplica | AP7: 46023 | AQ7: 2026-I | AR7: Asignado | AS7: =VLOOKUP(DemandaEstrateg_[[#This Row],[Últ. Estado CQ 30.04]],#REF!,3,FALSE) -> #REF! | AT7: =VLOOKUP(DemandaEstrateg_[[#This Row],[Estado TI]],#REF!,3,FALSE) -> #REF! | AU7: 24/10/24 Segun lo coordinar con Omar Cribillero, Prestamos por IVR se encuentra en Producción y Prestamos por Agentes fué desestimado en el ulitmo comité de Proyectos. 27/06/2024 Se regulariza su registro en la demanda Estratégica. 10/06/2024: Se registró en el Backlog de requerimientos | AV7: No Aplica
A8: 4 | E8: Proyecto-Hijo | F8: Proyecto 4 | H8: G1 | AH8: 45183 | AI8: 45723 | AK8: No aplica | AL8: No aplica | AM8: =IF(DemandaEstrateg_[[#This Row],[Tipo de Requerimiento]]="Proyecto",(DemandaEstrateg_[[#This Row],[% Avance ejecutado]]-DemandaEstrateg_[[#This Row],[% Avance Planificado]])/DemandaEstrateg_[[#This Row],[% Avance Planificado]],"No aplica") -> No aplica | AN8: =IF(DemandaEstrateg_[[#This Row],[Tipo de Requerimiento]]="Proyecto",(DemandaEstrateg_[[#This Row],[% Avance ejecutado]]-DemandaEstrateg_[[#This Row],[% Avance Planificado]])/DemandaEstrateg_[[#This Row],[% Avance Planificado]],"No aplica") -> No aplica | AP8: 46023 | AQ8: 2026-I | AR8: Asignado | AS8: =VLOOKUP(DemandaEstrateg_[[#This Row],[Últ. Estado CQ 30.04]],#REF!,3,FALSE) -> #REF! | AT8: =VLOOKUP(DemandaEstrateg_[[#This Row],[Estado TI]],#REF!,3,FALSE) -> #REF! | AU8: 31/12/24: Ciclos de pruebas en marcha (379 Ok / 617 Total). Se esta coordinando y resolviendo día a día con proveedor y TI. A la par ya culminaron con remitir solicitud de cambio y cronograma de actividades para que sea aprobado por el comité. 13/12/2024 El Proyecto se está certificando, se remitió nuevo cronograma con las nuevas fechas de implementación. 19/11/2024 Se aprobó un nuevo cronograma con fecha de incio del Piloto para Enero 2025. El proyecto se encuentra a un 74% de avance segun cronograma actualizado al 07 de Noviembre. 12/08/2024 Avance del Proyecto segun cronograma. 27/06/2024 Seregulariza su ingreso a la demanda estratégica. | AV8: No Aplica
A9: 5 | E9: Proyecto-Hijo | F9: Proyecto 5 | H9: G1 | AH9: 44726 | AI9: 45930 | AK9: No aplica | AL9: No aplica | AM9: =IF(DemandaEstrateg_[[#This Row],[Tipo de Requerimiento]]="Proyecto",(DemandaEstrateg_[[#This Row],[% Avance ejecutado]]-DemandaEstrateg_[[#This Row],[% Avance Planificado]])/DemandaEstrateg_[[#This Row],[% Avance Planificado]],"No aplica") -> No aplica | AN9: =IF(DemandaEstrateg_[[#This Row],[Tipo de Requerimiento]]="Proyecto",(DemandaEstrateg_[[#This Row],[% Avance ejecutado]]-DemandaEstrateg_[[#This Row],[% Avance Planificado]])/DemandaEstrateg_[[#This Row],[% Avance Planificado]],"No aplica") -> No aplica | AP9: 46082 | AQ9: 2026-I | AR9: Aprobado | AS9: =VLOOKUP(DemandaEstrateg_[[#This Row],[Últ. Estado CQ 30.04]],#REF!,3,FALSE) -> #REF! | AT9: =VLOOKUP(DemandaEstrateg_[[#This Row],[Estado TI]],#REF!,3,FALSE) -> #REF! | AU9: 13/12/2023: COMITÉ DEMANDA REGULARIZACIÓN: Se regulariza su registro según lo aprobado en comité | AV9: No Aplica
A10: 6 | E10: Proyecto-Hijo | F10: Proyecto 6 | H10: G1 | AH10: 45054 | AI10: 45869 | AK10: No aplica | AL10: No aplica | AM10: =IF(DemandaEstrateg_[[#This Row],[Tipo de Requerimiento]]="Proyecto",(DemandaEstrateg_[[#This Row],[% Avance ejecutado]]-DemandaEstrateg_[[#This Row],[% Avance Planificado]])/DemandaEstrateg_[[#This Row],[% Avance Planificado]],"No aplica") -> No aplica | AN10: =IF(DemandaEstrateg_[[#This Row],[Tipo de Requerimiento]]="Proyecto",(DemandaEstrateg_[[#This Row],[% Avance ejecutado]]-DemandaEstrateg_[[#This Row],[% Avance Planificado]])/DemandaEstrateg_[[#This Row],[% Avance Planificado]],"No aplica") -> No aplica | AP10: 46082 | AQ10: 2026-I | AR10: Aprobado | AS10: =VLOOKUP(DemandaEstrateg_[[#This Row],[Últ. Estado CQ 30.04]],#REF!,3,FALSE) -> #REF! | AT10: =VLOOKUP(DemandaEstrateg_[[#This Row],[Estado TI]],#REF!,3,FALSE) -> #REF! | AU10: 13/12/2023: COMITÉ DEMANDA REGULARIZACIÓN: Se regulariza su registro según lo aprobado en comité | AV10: No Aplica
A11: 7 | E11: Proyecto-Hijo | F11: Proyecto 7 | H11: G1 | AH11: 45236 | AI11: 45869 | AK11: No aplica | AL11: No aplica | AM11: =IF(DemandaEstrateg_[[#This Row],[Tipo de Requerimiento]]="Proyecto",(DemandaEstrateg_[[#This Row],[% Avance ejecutado]]-DemandaEstrateg_[[#This Row],[% Avance Planificado]])/DemandaEstrateg_[[#This Row],[% Avance Planificado]],"No aplica") -> No aplica | AN11: =IF(DemandaEstrateg_[[#This Row],[Tipo de Requerimiento]]="Proyecto",(DemandaEstrateg_[[#This Row],[% Avance ejecutado]]-DemandaEstrateg_[[#This Row],[% Avance Planificado]])/DemandaEstrateg_[[#This Row],[% Avance Planificado]],"No aplica") -> No aplica | AP11: 46082 | AQ11: 2026-I | AR11: Aprobado | AS11: =VLOOKUP(DemandaEstrateg_[[#This Row],[Últ. Estado CQ 30.04]],#REF!,3,FALSE) -> #REF! | AT11: =VLOOKUP(DemandaEstrateg_[[#This Row],[Estado TI]],#REF!,3,FALSE) -> #REF! | AU11: 13/12/2023: COMITÉ DEMANDA REGULARIZACIÓN: Se regulariza su registro según lo aprobado en comité | AV11: No Aplica
A12: 8 | E12: Proyecto-Hijo | F12: Proyecto 8 | H12: G1 | AH12: 44739 | AI12: 45838 | AJ12: 46050 | AK12: No aplica | AL12: No aplica | AM12: =IF(DemandaEstrateg_[[#This Row],[Tipo de Requerimiento]]="Proyecto",(DemandaEstrateg_[[#This Row],[% Avance ejecutado]]-DemandaEstrateg_[[#This Row],[% Avance Planificado]])/DemandaEstrateg_[[#This Row],[% Avance Planificado]],"No aplica") -> No aplica | AN12: =IF(DemandaEstrateg_[[#This Row],[Tipo de Requerimiento]]="Proyecto",(DemandaEstrateg_[[#This Row],[% Avance ejecutado]]-DemandaEstrateg_[[#This Row],[% Avance Planificado]])/DemandaEstrateg_[[#This Row],[% Avance Planificado]],"No aplica") -> No aplica | AP12: 45992 | AQ12: 2025-IV | AR12: Procesado | AS12: =VLOOKUP(DemandaEstrateg_[[#This Row],[Últ. Estado CQ 30.04]],#REF!,3,FALSE) -> #REF! | AT12: =VLOOKUP(DemandaEstrateg_[[#This Row],[Estado TI]],#REF!,3,FALSE) -> #REF! | AU12: 13/12/2023: COMITÉ DEMANDA REGULARIZACIÓN: Se regulariza su registro según lo aprobado en comité | AV12: No Aplica
A13: 9 | E13: Proyecto-Hijo | F13: Proyecto 9 | H13: G1 | AH13: 45045 | AI13: 45723 | AJ13: 46052 | AK13: No aplica | AL13: No aplica | AM13: =IF(DemandaEstrateg_[[#This Row],[Tipo de Requerimiento]]="Proyecto",(DemandaEstrateg_[[#This Row],[% Avance ejecutado]]-DemandaEstrateg_[[#This Row],[% Avance Planificado]])/DemandaEstrateg_[[#This Row],[% Avance Planificado]],"No aplica") -> No aplica | AN13: =IF(DemandaEstrateg_[[#This Row],[Tipo de Requerimiento]]="Proyecto",(DemandaEstrateg_[[#This Row],[% Avance ejecutado]]-DemandaEstrateg_[[#This Row],[% Avance Planificado]])/DemandaEstrateg_[[#This Row],[% Avance Planificado]],"No aplica") -> No aplica | AP13: 45992 | AQ13: 2025-IV | AR13: Procesado | AS13: =VLOOKUP(DemandaEstrateg_[[#This Row],[Últ. Estado CQ 30.04]],#REF!,3,FALSE) -> #REF! | AT13: =VLOOKUP(DemandaEstrateg_[[#This Row],[Estado TI]],#REF!,3,FALSE) -> #REF! | AU13: 17/10/2024: Según CQ, se actualizó el estado de 04. Desarrollo Finalizado a 05. En Calidad 13/12/2023: COMITÉ DEMANDA REGULARIZACIÓN: Se regulariza su registro según lo aprobado en comité | AV13: No Aplica
A14: 10 | E14: Proyecto-Hijo | F14: Proyecto 10 | H14: G1 | AH14: 45652 | AI14: 46139 | AK14: 0.71 | AL14: 0.51 | AM14: =IF(DemandaEstrateg_[[#This Row],[Tipo de Requerimiento]]="Proyecto",(DemandaEstrateg_[[#This Row],[% Avance ejecutado]]-DemandaEstrateg_[[#This Row],[% Avance Planificado]])/DemandaEstrateg_[[#This Row],[% Avance Planificado]],"No aplica") -> No aplica | AN14: =IF(DemandaEstrateg_[[#This Row],[Tipo de Requerimiento]]="Proyecto",(DemandaEstrateg_[[#This Row],[% Avance ejecutado]]-DemandaEstrateg_[[#This Row],[% Avance Planificado]])/DemandaEstrateg_[[#This Row],[% Avance Planificado]],"No aplica") -> No aplica | AP14: 46082 | AQ14: 2026-I | AR14: Certificado | AS14: =VLOOKUP(DemandaEstrateg_[[#This Row],[Últ. Estado CQ 30.04]],#REF!,3,FALSE) -> #REF! | AT14: =VLOOKUP(DemandaEstrateg_[[#This Row],[Estado TI]],#REF!,3,FALSE) -> #REF! | AU14: 29/08/2024: Según CQ, se actualizó el estado de 03. En Desarrollo a 05. En Calidad 13/12/2023: COMITÉ DEMANDA REGULARIZACIÓN: Se regulariza su registro según lo aprobado en comité | AV14: No Aplica
A15: 11 | E15: Proyecto | F15: Proyecto 11 | H15: G1 | AH15: ='Portafolio P&D'!Y9 -> 0 | AI15: ='Portafolio P&D'!Z9 -> 0 | AK15: 0.87 | AL15: 0.83 | AM15: =IF(DemandaEstrateg_[[#This Row],[Tipo de Requerimiento]]="Proyecto",(DemandaEstrateg_[[#This Row],[% Avance ejecutado]]-DemandaEstrateg_[[#This Row],[% Avance Planificado]])/DemandaEstrateg_[[#This Row],[% Avance Planificado]],"No aplica") -> -0.045977011 | AN15: =IF(DemandaEstrateg_[[#This Row],[Tipo de Requerimiento]]="Proyecto",(DemandaEstrateg_[[#This Row],[% Avance ejecutado]]-DemandaEstrateg_[[#This Row],[% Avance Planificado]])/DemandaEstrateg_[[#This Row],[% Avance Planificado]],"No aplica") -> -0.045977011 | AP15: 45931 | AQ15: 2026-I | AR15: Pendiente | AS15: 03. En Desarrollo | AT15: =VLOOKUP(DemandaEstrateg_[[#This Row],[Estado TI]],#REF!,3,FALSE) -> #REF! | AU15: 12/01/2026: Mediante correo del 07/12/2026, Luis Palacios Q. comunicó que las siguientes actividades del Realease 3 se encuentran pendientes de culminar para pasar a Producción: - Revisión y firma de Actas de Conformidad de pruebas funcionales, (Usuario Secc. Canales Virtuales) - Revisión del WorkBook de QR, nueva versión (4.0) - Cámara de Compensación E., (Marco Obando / Luis Palacios ) - Revisión de reportes contables (TEMENOS) - Pruebas de seguridad, (TEMENOS / Oficina de Seguridad Informática) 04/12/2025: Mediante correo del 01/12/2025, Karin Robles indicó el estado de los siguientes requerimientos del Realise 3: Pendiente de coordinación para pasar a Producción - Responsable BACKBASE 2024-M0299 Validación de identidad externa para enrolamiento en Cuenta DNI con registro de titular en línea: 05. En Calidad, Pruebas de Usuario FUNCIONAL: En revisión de las actas de conformidad por los Usuarios. Pruebas de RENDIMIENTO: Se cuenta con la APROBACIÓN del PO sobre los informes de Rendimiento Pruebas de SEGURIDAD: Se envió el informe y reporte de las pruebas al Proveedor de BACKBASE para su revisión y validación en conjunto con el área de Seguridad. 2025-M0071 Transferencias interbancarias inmediatas en la Aplicación móvil de Cuenta DNI 05. En Calidad 2025-M0072 Transferencias Interbancarias inmediatas a Celular (búsqueda de contactos) y con código QR en la Aplicación móvil de Cuenta DNI 05. En Calidad 2025-M0372 Integración del Orquestador de Novatronic con el Core de Cuenta DNI par transferencias inmediatas a otros Bancos. 05. En Calidad 2025-M0280 Integración de Orquestador para Transferencia Inmediata desde Cta. DNI – Servidor para tarifario dinámico (3 ambientes). 05. En Calidad 27/11/2025: Mediante correo del 27/11/2025, Luis Palacios indicóque presentaron una solicitud de cambio donde se estara llevando un mejor control del avance del proyecto, hasta el momento se han mantenido las fechas con los avances porcentuales correspondientes. 05/09/2025: Mediante correo del 04/09/2025, Luis Palacios indicó el estado de las siguientes actividades: - Transferencias inmediatas de entrada: Entrega pendiente de API por NOVATRONIC. - Transferencias Internas CTA-DNI a CTA-BN: pendiente el inicio de pruebas. BACKBASE propone realizar pruebas con postman al API de Novatronic. - Depósito / Retiro en Agentes Corresponsales – Entrega pendiente de API por NOVATRONIC. - Depósito / Retiro en Ventanilla – Inicio de pruebas integrales con SARAWEB (29.09.25). Está pendiente que el usuario gestione la ampliación de plazo e informar a Planeamiento. 25/07/2025:• MP2 (R3) Se han culminado las pruebas funcionales (2do ciclo) en Calidad. Está pendiente la atención de las observaciones por parte del proveedor para dar inicio al 3er ciclo de pruebas. Está pendiente ejecutar las pruebas de rendimiento. Se estima su pase a producción agosto 2025 • MPV 3 (R4) Se encuentra con un avance de 50%, se entregó las Especificaciones técnicas de las APIs para el desarrollo de Novatronic para agentes y transferencia de entrada. En proceso el desarrollo de retiro y deposito por ventanilla. Luego de ello se realizará una prueba integral. Se estima su pase a producción Nov_2025. En coordinaciones con usuario para la actualizacion del cronograma. 7/07/2025: Según lo informado por el usuario LPalacios mediante correo del 17.07 indico: • MP2 (R3) Se encuentra con un avance de 90% quedando pendientes ejecutar las pruebas de rendimiento. Se estima su pase a producción agosto 2025 • MPV 3 (R4) Se encuentra con un avance de 50%, se entregará las Especificaciones técnicas de las APIs para el desarrollo de Novatronic. Luego de ello se realizará una prueba integral. Se estima su pase a producción Nov_2025 Estas fechas deberían ser comunicado a la Gerencia de Planeamiento. 11/06/2025:Según la información enviada de Planeamiento en el mes de Mayo se precisa lo siguiente: Durante la ejecución de las pruebas integrales en el entorno de desarrollo, en las que participan los tres proveedores (Backbase, Temenos y Novatronic), se han identificado incidencias relacionadas con la conexión a la Cámara de Compensaciones y con los tiempos de respuesta en las operaciones correspondientes al proceso de interoperabilidad (transferencias interbancarias inmediatas y pagos con QR). -Estas situaciones vienen siendo atendidas de manera conjunta por Novatronic, Temenos y el Banco de la Nación. 03/06/2025: Según la información enviada de Planeamiento mediante correo respecto al proyecto en el mes de abril se tiene que: Durante las pruebas integrales (participación de los 3 proveedores) se presentó incidencias con el tarifario dinámico que interactúa con todo el proceso de interoperabilidad (transferencias interbancarias inmediatas, pago con QR) la que está siendo atendidas por Novatronic. Asimismo, el proveedor Tenemos, presentó incidente en la data que se trasmite al core T24. Se realizan reuniones de seguimiento 2 veces al día para el seguimiento de las pruebas y corrección de los incidentes Se estima culminar las pruebas en desarrollo la primera semana de mayo iniciar pruebas en el ambiente de Calidad. 07/05/2025: Según la información enviada por Planeamiento mediante correo: Se continúan las pruebas en desarrollo de las funcionalidades de transferencias inmediatas, por contacto y QR con el proveedor BACKBASE, TEMENOS y NOVATRONIC. Se mantienen las pruebas en desarrollo de las funcionalidades de retiro y deposito en agente BN y para retiro y depósito en ventanilla con el proveedor TEMENOS y el BN. 31/12/2024: Las áreas usuarias validaron las funcionalidades de retiro y depósito en Ventanilla y se procedió con la generación del Anexo 2 para solicitar la inscripción en el Clear Quest. Se continúan coordinando con el proveedor Temenos para correcciones. Siguen en construcción la funcionalidad de transferencias Q 23/05/24 Mediante comité estratégico de proyectos con fecha 06.05.24 se aprobó el control de cambios del proyecto.Esto implica nuevas actividades y actualizacion en el cronograma. TI solicitará al usuario remtiir anexo 1 actualizado. 08/04/24 Se cambió la fecha de Fin de proyecto a 2025 20/03/24 Usuario remitió modelo de negocio y se registró en la demanda estrategica de TI, sin embargo se encuentra pendiente que el usuario remita modelo de negocio actualizado. Está retrasado porque el proveedor no contempló dentro del cronograma actividades funcionales que son necesarias para el proytecto. Presentarán un control de cambios a nivel de alcance, tiempo y presupuesto. 03/06/2025: Según la información enviada de Planeamiento mediante correo respecto al proyecto en el mes de abril se tiene que: Durante las pruebas integrales (participación de los 3 proveedores) se presentó incidencias con el tarifario dinámico que interactúa con todo el proceso de interoperabilidad (transferencias interbancarias inmediatas, pago con QR) la que está siendo atendidas por Novatronic. Asimismo, el proveedor Tenemos, presentó incidente en la data que se trasmite al core T24. Se realizan reuniones de seguimiento 2 veces al día para el seguimiento de las pruebas y corrección de los incidentes Se estima culminar las pruebas en desarrollo la primera semana de mayo iniciar pruebas en el ambiente de Calidad. 30/04/25: Según lo informado por el usuario LPalacios mediante correo, la fecha fin del proyecto que estaba proyectado de culminar en abril ahora se indica lo siguiente: • Transferencias inmediatas: Fines de mayo a quincena de junio. • Depósito / Retiro en Ventanilla: Fines de mayo a quincena de junio. • Depósito / Retiro en agentes: fines de junio a quincena de julio. 04/04/25: Según lo informado por el usuario LPalacios mediante correo del 28/03, la fecha fin del proyecto estaba programado para el 30 de marzo, sin embargo, todavía existe dependencias de los proveedores, por lo que se proyecta culminar con el Proyecto el 30 de abril.. 28/02/2025: Transferencias Interbancarias Inmediatas (CCI, QR, Contacto), Transferencias Internas CTA-BN a CTA-DNI, Retiro/Depósito Agentes Corresponsales, Retiro y Depósito en Ventanilla se encuentran en Desarrollo. Usuario remitió 1 nuevo requerimiento asociado al Proyecto, el mismo que se encuentran en Desarrollo 21/03/25: Mediante correo del 21/03/25 de Planeamiento se indica: Se encuentra en pruebas de desarrollo las funcionalidades de transferencias inmediatas, por contacto y QR con el proveedor BACKBASE, TEMENOS y NOVATRONIC. Se han culminado las pruebas en certificación para las funcionalides de Generación de Estados de Cuenta y Cambio de CCI con el proveedor TEMENOS. Para la quincena de marzo se espera el pase a producción 17/01/25 En proceso de atención 28/01/25 El desarrollo asociado a Saraweb (2024-M0299-Validación de identidad externa para enrolamiento en Cuenta DNI con registro de titular en línea) está culminado. A espera que el proveedor realice el cambio en su API para retomar las pruebas de integración. Usuario remitió 3 nuevos requerimientos asociados al Proyecto, el mismo que se encuentran en Planificación. 31/12/24: Las áreas usuarias validaron las funcionalidades de retiro y depósito en Ventanilla y se procedió con la generación del Anexo 2 para solicitar la inscripción en el Clear Quest. Se continúan coordinando con el proveedor Temenos para correcciones. 20/03/24 Usuario remitió modelo de negocio y se registró en la demanda estrategica de TI, sin embargo se encuentra pendiente que el usuario remita modelo de negocio actualizado. Según lo informado por Planeamiento, el Py está retrasado porque el proveedor no contempló dentro del cronograma actividades funcionales, que son necesarias para el proyecto. Presentarán un control de cambios a nivel de alcance, tiempo y presupuesto e informarán a TI. 16/02/2024: COMITE EXCPECIONAL: Se realiza su priorización El Proyecto fue priorizado por el Ejecutivo de Proyecto, se tiene el Anexo 1 - Modelo de Negocio. Usuario remitó requerimiento para enrolamiento con Bioemtría facial. | AV15: ='Portafolio P&D'!B9 -> 0
A16: 12 | E16: Proyecto | F16: Proyecto 12 | H16: G1 | AG16: No aplica | AH16: ='Portafolio P&D'!Y12 -> 0 | AI16: ='Portafolio P&D'!Z12 -> 0 | AK16: ='Portafolio P&D'!AA12 -> 1 | AL16: ='Portafolio P&D'!AB12 -> 1 | AM16: =IF(DemandaEstrateg_[[#This Row],[Tipo de Requerimiento]]="Proyecto",(DemandaEstrateg_[[#This Row],[% Avance ejecutado]]-DemandaEstrateg_[[#This Row],[% Avance Planificado]])/DemandaEstrateg_[[#This Row],[% Avance Planificado]],"No aplica") -> 0 | AN16: =IF(DemandaEstrateg_[[#This Row],[Tipo de Requerimiento]]="Proyecto",(DemandaEstrateg_[[#This Row],[% Avance ejecutado]]-DemandaEstrateg_[[#This Row],[% Avance Planificado]])/DemandaEstrateg_[[#This Row],[% Avance Planificado]],"No aplica") -> 0 | AP16: 45748 | AQ16: 2025-II | AR16: Pendiente | AS16: 09. Finalizado | AT16: =VLOOKUP(DemandaEstrateg_[[#This Row],[Estado TI]],#REF!,3,FALSE) -> #REF! | AU16: 17/07/2025: El Proyecto Culminó en el mes de abril2025. 11/06/2025:Según la información enviada de Planeamiento en el mes de Mayo se precisa lo siguiente: El Equipo Técnico del proyecto informó que, se culminó con la implementación al 100%. Asimismo, se presentó el avance de las siguientes actividades: Implementación: Ejecución: 100% (finalizado) Monitoreo y Control: 100% (finalizado) Cierre 100% (finalizado) 03/06/2025: Según la información enviada de Planeamiento mediante correo respecto al proyecto en el mes de abril se tiene que: El proyecto ha sido culminado. Fin del Proyecto. 21/05/2025: Según el Acta de Reunión N°04-2025 del Comité de Proyectos, se enviará a Planeamiento el Acta de Cierre del Proyecto y el fomato de lecciones aprendidas en las próximas semanas. 07/05/2025: Según la información remitida por Planeamiento mediante correo: A nivel tareas, actualmente se encuentra en la Etapa de Implementación del Proyecto. El Equipo Técnico del proyecto informó que, solo faltan instalar 45 equipos de 547 nuevos equipos en la Red de Agencias. Además, se revisaron posibles riesgos y desafíos que podrían impactar el cronograma, con el objetivo de tomar medidas preventivas y correctivas. Finalmente, se comunicó que las actividades del proyecto se vienen realizando de acuerdo a lo planificado. Asimismo, se presentó el avance de las siguientes actividades: • Implementación: Ejecución: 96% (en proceso) Monitoreo y Control: 97% (casi finalizado) 31/12/2024: *Se instalaron 280 switches para las sedes administrativas así como la implementación de los servidores plataforma de gestión, la solución NAC y Control de accesos. Dado esto, se viene realizando la entrega de la conformidad del servicio para el pago correspondiente por esta primera etapa. * Los usuarios de Canales Virtuales y Red de Agencias solicitaron no realizar trabajos durante esta semana por lo que se suspenden las actividades hasta el mes de enero. 23/05/24 Validar si se firmó el contrato. A espera que el proveedor entregue el plan de trabajo. 25/04/2024 Mediante Memo N° 63-2024-BN2810 en que se entrega la nueva lista de proyectos con componente TI se genera cambio en el lider del proyecto de José Macedo a Alejandro Sifuentes 25/04/2024 Mediante Memo N°60-2024-BN2810 se informa que se requiere el informe de las razones del retraso del proyecto asi como sus acciones correctivas para la presentación al comité del 26.04 20/03/24 Esta en proceso logistico (analisis de oferta y la buena pro se dará en marzo). Presentarán un nuevo cronograma con control de cambios. 03/06/2025: Según la información enviada de Planeamiento mediante correo respecto al proyecto en el mes de abril se tiene que el proyecto ha sido culminado. 21/05/2025: Según el Acta de Reunión N°04-2025 del Comité de Proyectos, se enviará a Planeamiento el Acta de Cierre del Proyecto y el fomato de lecciones aprendidas en las próximas semanas. 30/04/2025: El Equipo Técnico del proyecto informó que, se culminó con la implementación al 100%. Finalmente, también se comunicó que las actividades del proyecto se realizaron de acuerdo a lo planificado. Se comunicará y se enviará a la G. de Planeamiento el Acta de Cierre de proyecto y lecciones aprendidas 31/03/2025: Las actividades del proyecto se vienen realizando de acuerdo a lo planificado. Actualmente, solo faltan instalar 45 equipos de 547 nuevos equipos en la red de agencias. 21/03/25: Mediante correo del 21/03/25 de Planeamiento se indica: El Equipo Técnico del proyecto seguirá apoyando al proveedor en la instalación de switches en lobbys, agencias y oficinas especiales, reafirmando su compromiso con el éxito del proyecto. Para asegurar el cumplimiento del cronograma, el Equipo Técnico hará un seguimiento constante del avance de la instalación e informará sobre los hitos alcanzados. Si es necesario, se gestionará un control de cambio para ajustar el cronograma a las nuevas fechas y mantener la alineación con los objetivos del proyecto. 28/02/2025: El Equipo Técnico del proyecto informó que, desde febrero, ha estado brindando apoyo al Proveedor en la instalación de Switches en lobbys, agencias y oficinas especiales. Además, se revisaron posibles riesgos y desafíos que podrían impactar el cronograma, con el objetivo de tomar medidas preventivas y correctivas. Asimismo, se presentó el avance de las siguientes actividades: • Implementación: Planificación: 100% (completada) , Ejecución: 48% (en proceso), Monitoreo y Control: 94% (casi finalizado) 17/02/2025: El Proveedor esta realizando las actividades segun lo planificado en el nuevo cronograma, al respecto el Equipo Técnico del proyecto en caso de que sea necesario, solicitará un control de cambio, a fin de ajustar el cronograma conforme a las nuevas fechas. 31/01/2025:Se informa que el 13.01.2025 el BN recibe la solicitud de ampliación de plazo N°01 presentada por el contratista CONSORCIO ALFIL CONSULTORIA Y COMUNICACIONES S.A.C. - ADISTEC PERU S.A.C. donde solicitan 32 (treinta y dos) días calendario de ampliación del plazo contractual al contrato esto debido a que en el mes de diciembre 2024, las actividades fueron suspendidas a pedido del área usuaria (Sección Canales Presenciales de la Subgerencia Canales Alternos de la Gerencia Banca Digital). El 25/01/2025, la Sección Soporte de la Infraestructura emite el informe N° 022-2025-BN/2574 solicitado por la Sección Seguimiento Administrativo de contratos mediante Memorando N° 041-2025-BN/2664 el 14/01/2025. Finalmente, el 27/01/2025, Mediante Resolución de Gerencia de Administración y Logistica N° 007-2025-BN/5500, declara procedente la solicitud de ampliación de plazo N°01 presentada por el contratista CONSORCIO ALFIL CONSULTORIA Y COMUNICACIONES S.A.C. - ADISTEC PERU S.A.C. con fecha 13/01/2025, toda vez que cumple con los requisitos establecidos por ley. 31/12/24: *Se instalaron 280 switches para las sedes administrativas así como la implementación de los servidores plataforma de gestión, la solución NAC y Control de accesos. Dado esto, se viene realizando la entrega de la conformidad del servicio para el pago correspondiente por esta primera etapa. * Los usuarios de Canales Virtuales y Red de Agencias solicitaron no realizar trabajos durante esta semana por lo que se suspenden las actividades hasta el mes de enero. 13/12/2024: Se informó el avance de las siguientes actividades: Planificación: 95%, Ejecución: 40%, Monitoreo y Control: 82%.. Se culminó con la instalacion en la Sede Principal de San Borja y Elizalde. Nos informaron que el nuevo Líder Técnico es el analista Alberth Rivera 08/11/2024: Se informó el avance de las siguientes actividades: Planificación: 95%, Ejecución: 34%, Monitoreo y Control: 68%. Solo queda pendiente la instalación de switches en el piso 1 y el Network Access Control – NAC, progreso al 80%. 26/09/2024: Se informó el avance de las siguientes actividades: Planificación: 95%, Ejecución: 17%, Monitoreo y Control: 53% 09/08/2024: Durante el mes de agosto se realizarán actividades de instalación de Switches en el Local de Elizalde y San Borja. Actualmente se encuentra en la Etapa de Implementación del Proyecto y se realizan las actividades según el Plan de Trabajo presentado por el Proveedor. 11/07/2024: Se acepto el Control de Cambio para sincerar las fechas del cronograma de actividades, el Proyecto se desarrolla segun lo planificado. 21/06/24 El 02/05/2024 se firmó el Contrato y el 17/05/2024 se realizó la reunión de kickoff con la presentación y aprobación del Plan de Trabajo por parte del Proveedor. Actualmente se encuentra en la Etapa de Implementación del Proyecto, asimismo el Equipo del proyecto presentó Control de Cambio a la Gerencia de Planeamiento, para sincerar las fechas del cronograma. 03/05/24 La buena pro se dio el 22/03/24, actualmente se están revisando los documentos para la firma del contrato. Proyecto aprobado por P&D y comunicado a TI mediante MEMORANDO N° 00000201 - 2023-BN/2810 | AV16: ='Portafolio P&D'!B12 -> 0
